Workbook

Sheet 目次
A1: 現場技術業務 検査受検資料 目次
A2: 令和8年7月分
A4: 業務番号 | C4: 丹後７府民協働第１４９９の２号の２の１他1件
A5: 業務名 | C5: 管内一円 府民協働型インフラ保全業務委託 他１件
A6: 対象期間 | C6: 令和8年7月1日（水）～ 令和8年7月31日（金） 履行日数 22日（業務処理結果報告書 №62～№83）
A7: 適用仕様書 | C7: 現場技術業務委託共通仕様書（京都府）及び 現場技術業務 特記仕様書
A9: １．資料構成
A10: No. | B10: 資料名 | E10: 内容 | H10: 備考
A11: 1 | B11: 目次 | E11: 本表
A12: 2 | B12: 条文別整理表 | E12: 業務処理結果報告書の実施業務を共通仕様書の条文別に整理
A13: 3 | B13: 条文別集計 | E13: 条文別・実施日別の件数集計
A14: 4 | B14: 条文マスタ | E14: 現場技術業務委託共通仕様書 条文一覧・要旨
A15: 5 | B15: 業務処理結果報告書 | E15: 令和8年7月1日～7月31日（№62～№83、22日分） | H15: 別綴り（日報原本）
A17: ２．条文別索引（条文別整理表）
A18: 条文番号 | B18: 見出し | C18: 件数 | D18: 実施日数 | E18: 実施日 | F18: 該当 業務処理結果報告書№ | G18: 整理表 頁 | H18: 備考
A19: 第3条第3項(1) | B19: =INDEX(条文マスタ!$C$5:$C$24,MATCH($A19,条文マスタ!$A$5:$A$24,0)) -> 管理技術者等（監督に関する業務の厳正な実施） | C19: =INDEX(条文別集計!$Z$6:$Z$25,MATCH($A19,条文別集計!$A$6:$A$25,0)) -> 0 | D19: =INDEX(条文別集計!$AA$6:$AA$25,MATCH($A19,条文別集計!$A$6:$A$25,0)) -> 0 | E19: ― | F19: ― | G19: 1 | H19: 当月該当なし
A20: 第3条第3項(4) | B20: =INDEX(条文マスタ!$C$5:$C$24,MATCH($A20,条文マスタ!$A$5:$A$24,0)) -> 管理技術者等（工事請負者等への連絡・通知） | C20: =INDEX(条文別集計!$Z$6:$Z$25,MATCH($A20,条文別集計!$A$6:$A$25,0)) -> 0 | D20: =INDEX(条文別集計!$AA$6:$AA$25,MATCH($A20,条文別集計!$A$6:$A$25,0)) -> 0 | E20: ― | F20: ― | G20: 1 | H20: 当月該当なし
A21: 第3条第3項(5) | B21: =INDEX(条文マスタ!$C$5:$C$24,MATCH($A21,条文マスタ!$A$5:$A$24,0)) -> 管理技術者等（設計図書の理解・現場状況の精通） | C21: =INDEX(条文別集計!$Z$6:$Z$25,MATCH($A21,条文別集計!$A$6:$A$25,0)) -> 1 | D21: =INDEX(条文別集計!$AA$6:$AA$25,MATCH($A21,条文別集計!$A$6:$A$25,0)) -> 1 | E21: 7/7 | F21: №66 | G21: 1
A22: 第3条第3項(6) | B22: =INDEX(条文マスタ!$C$5:$C$24,MATCH($A22,条文マスタ!$A$5:$A$24,0)) -> 管理技術者等（図書の整理） | C22: =INDEX(条文別集計!$Z$6:$Z$25,MATCH($A22,条文別集計!$A$6:$A$25,0)) -> 7 | D22: =INDEX(条文別集計!$AA$6:$AA$25,MATCH($A22,条文別集計!$A$6:$A$25,0)) -> 4 | E22: 7/1、7/2、7/6、7/7 | F22: №62、№63、№65、№66 | G22: 1
A23: 第3条第4項 | B23: =INDEX(条文マスタ!$C$5:$C$24,MATCH($A23,条文マスタ!$A$5:$A$24,0)) -> 管理技術者等（監督職員との打合せ・協議） | C23: =INDEX(条文別集計!$Z$6:$Z$25,MATCH($A23,条文別集計!$A$6:$A$25,0)) -> 0 | D23: =INDEX(条文別集計!$AA$6:$AA$25,MATCH($A23,条文別集計!$A$6:$A$25,0)) -> 0 | E23: ― | F23: ― | G23: 1 | H23: 当月該当なし
A24: 第5条 | B24: =INDEX(条文マスタ!$C$5:$C$24,MATCH($A24,条文マスタ!$A$5:$A$24,0)) -> 業務処理予定表及び結果報告書 | C24: =INDEX(条文別集計!$Z$6:$Z$25,MATCH($A24,条文別集計!$A$6:$A$25,0)) -> 22 | D24: =INDEX(条文別集計!$AA$6:$AA$25,MATCH($A24,条文別集計!$A$6:$A$25,0)) -> 22 | E24: 全履行日（22日） | F24: №62～№83 | G24: 1
A25: 第6条 | B25: =INDEX(条文マスタ!$C$5:$C$24,MATCH($A25,条文マスタ!$A$5:$A$24,0)) -> 業務完了時の提出書類 | C25: =INDEX(条文別集計!$Z$6:$Z$25,MATCH($A25,条文別集計!$A$6:$A$25,0)) -> 0 | D25: =INDEX(条文別集計!$AA$6:$AA$25,MATCH($A25,条文別集計!$A$6:$A$25,0)) -> 0 | E25: ― | F25: ― | G25: 2 | H25: 当月該当なし
A26: 第7条 | B26: =INDEX(条文マスタ!$C$5:$C$24,MATCH($A26,条文マスタ!$A$5:$A$24,0)) -> 書類の確認 | C26: =INDEX(条文別集計!$Z$6:$Z$25,MATCH($A26,条文別集計!$A$6:$A$25,0)) -> 2 | D26: =INDEX(条文別集計!$AA$6:$AA$25,MATCH($A26,条文別集計!$A$6:$A$25,0)) -> 2 | E26: 7/21、7/23 | F26: №75、№77 | G26: 2
A27: 第8条 | B27: =INDEX(条文マスタ!$C$5:$C$24,MATCH($A27,条文マスタ!$A$5:$A$24,0)) -> 立会 | C27: =INDEX(条文別集計!$Z$6:$Z$25,MATCH($A27,条文別集計!$A$6:$A$25,0)) -> 8 | D27: =INDEX(条文別集計!$AA$6:$AA$25,MATCH($A27,条文別集計!$A$6:$A$25,0)) -> 6 | E27: 7/7、7/8、7/16、7/17、7/23、7/24 | F27: №66、№67、№73、№74、№77、№78 | G27: 2
A28: 第9条 | B28: =INDEX(条文マスタ!$C$5:$C$24,MATCH($A28,条文マスタ!$A$5:$A$24,0)) -> 検測 | C28: =INDEX(条文別集計!$Z$6:$Z$25,MATCH($A28,条文別集計!$A$6:$A$25,0)) -> 0 | D28: =INDEX(条文別集計!$AA$6:$AA$25,MATCH($A28,条文別集計!$A$6:$A$25,0)) -> 0 | E28: ― | F28: ― | G28: 2 | H28: 当月該当なし
A29: 第10条 | B29: =INDEX(条文マスタ!$C$5:$C$24,MATCH($A29,条文マスタ!$A$5:$A$24,0)) -> 材料検査 | C29: =INDEX(条文別集計!$Z$6:$Z$25,MATCH($A29,条文別集計!$A$6:$A$25,0)) -> 0 | D29: =INDEX(条文別集計!$AA$6:$AA$25,MATCH($A29,条文別集計!$A$6:$A$25,0)) -> 0 | E29: ― | F29: ― | G29: 2 | H29: 当月該当なし
A30: 第11条 | B30: =INDEX(条文マスタ!$C$5:$C$24,MATCH($A30,条文マスタ!$A$5:$A$24,0)) -> 工程管理 | C30: =INDEX(条文別集計!$Z$6:$Z$25,MATCH($A30,条文別集計!$A$6:$A$25,0)) -> 3 | D30: =INDEX(条文別集計!$AA$6:$AA$25,MATCH($A30,条文別集計!$A$6:$A$25,0)) -> 3 | E30: 7/1、7/10、7/22 | F30: №62、№69、№76 | G30: 2
A31: 第12条 | B31: =INDEX(条文マスタ!$C$5:$C$24,MATCH($A31,条文マスタ!$A$5:$A$24,0)) -> 品質管理 | C31: =INDEX(条文別集計!$Z$6:$Z$25,MATCH($A31,条文別集計!$A$6:$A$25,0)) -> 0 | D31: =INDEX(条文別集計!$AA$6:$AA$25,MATCH($A31,条文別集計!$A$6:$A$25,0)) -> 0 | E31: ― | F31: ― | G31: 3 | H31: 当月該当なし
A32: 第13条 | B32: =INDEX(条文マスタ!$C$5:$C$24,MATCH($A32,条文マスタ!$A$5:$A$24,0)) -> 図面と現地の不一致等 | C32: =INDEX(条文別集計!$Z$6:$Z$25,MATCH($A32,条文別集計!$A$6:$A$25,0)) -> 0 | D32: =INDEX(条文別集計!$AA$6:$AA$25,MATCH($A32,条文別集計!$A$6:$A$25,0)) -> 0 | E32: ― | F32: ― | G32: 3 | H32: 当月該当なし
A33: 第14条 | B33: =INDEX(条文マスタ!$C$5:$C$24,MATCH($A33,条文マスタ!$A$5:$A$24,0)) -> 検査の立会 | C33: =INDEX(条文別集計!$Z$6:$Z$25,MATCH($A33,条文別集計!$A$6:$A$25,0)) -> 4 | D33: =INDEX(条文別集計!$AA$6:$AA$25,MATCH($A33,条文別集計!$A$6:$A$25,0)) -> 3 | E33: 7/23、7/30、7/31 | F33: №77、№82、№83 | G33: 3
A34: 第15条 | B34: =INDEX(条文マスタ!$C$5:$C$24,MATCH($A34,条文マスタ!$A$5:$A$24,0)) -> 設計変更工事検査等に関する図書 | C34: =INDEX(条文別集計!$Z$6:$Z$25,MATCH($A34,条文別集計!$A$6:$A$25,0)) -> 26 | D34: =INDEX(条文別集計!$AA$6:$AA$25,MATCH($A34,条文別集計!$A$6:$A$25,0)) -> 11 | E34: 7/9、7/15、7/16、7/17、7/21、7/22、7/23、7/27、7/28、7/29、7/31 | F34: №68、№72、№73、№74、№75、№76、№77、№79、№80、№81、№83 | G34: 3
A35: 第16条 | B35: =INDEX(条文マスタ!$C$5:$C$24,MATCH($A35,条文マスタ!$A$5:$A$24,0)) -> 対外接渉に関する資料 | C35: =INDEX(条文別集計!$Z$6:$Z$25,MATCH($A35,条文別集計!$A$6:$A$25,0)) -> 0 | D35: =INDEX(条文別集計!$AA$6:$AA$25,MATCH($A35,条文別集計!$A$6:$A$25,0)) -> 0 | E35: ― | F35: ― | G35: 3 | H35: 当月該当なし
A36: 第17条 | B36: =INDEX(条文マスタ!$C$5:$C$24,MATCH($A36,条文マスタ!$A$5:$A$24,0)) -> 書面での報告 | C36: =INDEX(条文別集計!$Z$6:$Z$25,MATCH($A36,条文別集計!$A$6:$A$25,0)) -> 0 | D36: =INDEX(条文別集計!$AA$6:$AA$25,MATCH($A36,条文別集計!$A$6:$A$25,0)) -> 0 | E36: ― | F36: ― | G36: 3 | H36: 当月該当なし
A37: 第19条 | B37: =INDEX(条文マスタ!$C$5:$C$24,MATCH($A37,条文マスタ!$A$5:$A$24,0)) -> 設計に必要な調査 | C37: =INDEX(条文別集計!$Z$6:$Z$25,MATCH($A37,条文別集計!$A$6:$A$25,0)) -> 15 | D37: =INDEX(条文別集計!$AA$6:$AA$25,MATCH($A37,条文別集計!$A$6:$A$25,0)) -> 8 | E37: 7/3、7/6、7/9、7/10、7/16、7/24、7/30、7/31 | F37: №64、№65、№68、№69、№73、№78、№82、№83 | G37: 3
A38: 第20条 | B38: =INDEX(条文マスタ!$C$5:$C$24,MATCH($A38,条文マスタ!$A$5:$A$24,0)) -> 設計に必要な資料 | C38: =INDEX(条文別集計!$Z$6:$Z$25,MATCH($A38,条文別集計!$A$6:$A$25,0)) -> 9 | D38: =INDEX(条文別集計!$AA$6:$AA$25,MATCH($A38,条文別集計!$A$6:$A$25,0)) -> 5 | E38: 7/8、7/10、7/13、7/14、7/15 | F38: №67、№69、№70、№71、№72 | G38: 4
A39: 合計 | C39: =SUM(C19:C38) -> 97 | D39: =条文別集計!AA26 -> 22
A41: ※ 条文番号をクリックすると「条文別整理表」の該当箇所へ移動。件数・実施日数は「条文別集計」から参照。
A42: ※ 「整理表 頁」は条文別整理表をA4横で印刷した際のページ番号（フッター「条文別整理表 p.○」に対応）。
A43: ※ 日常定型業務（業務内容打合せ・翌日作業打合せ・報告書作成）は第5条に1日1件として計上。

Sheet 条文別整理表
A1: 現場技術業務 検査受検資料 条文別整理表（令和8年7月分）
A3: 業務番号 | C3: 丹後７府民協働第１４９９の２号の２の１他1件
A4: 業務名 | C4: 管内一円 府民協働型インフラ保全業務委託 他１件
A5: 対象期間 | C5: 令和8年7月1日（水）～ 令和8年7月31日（金） 履行日数 22日（業務処理結果報告書 №62～№83）
A6: 適用仕様書 | C6: 現場技術業務委託共通仕様書（京都府）及び 現場技術業務 特記仕様書
A8: 条文番号 | B8: 見出し | C8: No. | D8: 実施日 | E8: 曜 | F8: 開始時刻 | G8: 対象工事・業務 | H8: 実施内容 | I8: 相手先／検査官 | J8: 担当監督員 | K8: 報告書№ | L8: 備考
A9: 第3条第3項(1) | B9: =INDEX(条文マスタ!$C$5:$C$24,MATCH($A9,条文マスタ!$A$5:$A$24,0)) -> 管理技術者等（監督に関する業務の厳正な実施） | G9: =INDEX(条文マスタ!$D$5:$D$24,MATCH($A9,条文マスタ!$A$5:$A$24,0)) -> 必要な監督に関する業務を厳正に実施すること。 | I9: =COUNT($C$10:$C$10)&"件" -> 0件 | J9: 実施日数 | K9: =IF(COUNT($C$10:$C$10)=0,0,SUMPRODUCT(($C$10:$C$10<>"")/COUNTIFS($D$10:$D$10,$D$10:$D$10&"")))&"日" -> 0日
A10: 第3条第3項(1) | H10: 当月該当業務なし
A11: 第3条第3項(4) | B11: =INDEX(条文マスタ!$C$5:$C$24,MATCH($A11,条文マスタ!$A$5:$A$24,0)) -> 管理技術者等（工事請負者等への連絡・通知） | G11: =INDEX(条文マスタ!$D$5:$D$24,MATCH($A11,条文マスタ!$A$5:$A$24,0)) -> 工事請負者又は外部への連絡若しくは通知を行う場合には、その内容を相手に正確に伝えること。 | I11: =COUNT($C$12:$C$12)&"件" -> 0件 | J11: 実施日数 | K11: =IF(COUNT($C$12:$C$12)=0,0,SUMPRODUCT(($C$12:$C$12<>"")/COUNTIFS($D$12:$D$12,$D$12:$D$12&"")))&"日" -> 0日
A12: 第3条第3項(4) | H12: 当月該当業務なし
A13: 第3条第3項(5) | B13: =INDEX(条文マスタ!$C$5:$C$24,MATCH($A13,条文マスタ!$A$5:$A$24,0)) -> 管理技術者等（設計図書の理解・現場状況の精通） | G13: =INDEX(条文マスタ!$D$5:$D$24,MATCH($A13,条文マスタ!$A$5:$A$24,0)) -> 請負工事の契約書及び設計図書等の内容を十分理解し、更に工事現場の状況についても精通しておくこと。 | I13: =COUNT($C$14:$C$14)&"件" -> 1件 | J13: 実施日数 | K13: =IF(COUNT($C$14:$C$14)=0,0,SUMPRODUCT(($C$14:$C$14<>"")/COUNTIFS($D$14:$D$14,$D$14:$D$14&"")))&"日" -> 1日
A14: 第3条第3項(5) | C14: 1 | D14: 46210 | E14: =MID("日月火水木金土",WEEKDAY(D14),1) -> 火 | F14: PM1:00 | G14: 管内一円（河梨川他）府民協働型インフラ保全工事 | H14: 現場状況確認 (久美浜・川上谷川） | I14: 西田建設㈱ | J14: 倉垣副主査 | K14: 66
A15: 第3条第3項(6) | B15: =INDEX(条文マスタ!$C$5:$C$24,MATCH($A15,条文マスタ!$A$5:$A$24,0)) -> 管理技術者等（図書の整理） | G15: =INDEX(条文マスタ!$D$5:$D$24,MATCH($A15,条文マスタ!$A$5:$A$24,0)) -> 業務の実施にあたっては、業務に関する図書を適切に整理しておくこと。 | I15: =COUNT($C$16:$C$22)&"件" -> 7件 | J15: 実施日数 | K15: =IF(COUNT($C$16:$C$22)=0,0,SUMPRODUCT(($C$16:$C$22<>"")/COUNTIFS($D$16:$D$22,$D$16:$D$22&"")))&"日" -> 4日
A16: 第3条第3項(6) | C16: 1 | D16: 46204 | E16: =MID("日月火水木金土",WEEKDAY(D16),1) -> 水 | F16: AM11:30 | G16: 現場技術業務 | H16: 業務検査報告書類取り纏め | K16: 62
A17: 第3条第3項(6) | C17: 2 | D17: 46204 | E17: =MID("日月火水木金土",WEEKDAY(D17),1) -> 水 | F17: PM1:00 | G17: 現場技術業務 | H17: 業務検査報告書類取り纏め | K17: 62
A18: 第3条第3項(6) | C18: 3 | D18: 46205 | E18: =MID("日月火水木金土",WEEKDAY(D18),1) -> 木 | F18: AM9:00 | G18: 現場技術業務 | H18: 業務検査報告書類取り纏め | J18: 小林主査 | K18: 63
A19: 第3条第3項(6) | C19: 4 | D19: 46205 | E19: =MID("日月火水木金土",WEEKDAY(D19),1) -> 木 | F19: PM1:00 | G19: 現場技術業務 | H19: 業務検査報告書類取り纏め | J19: 小林主査 | K19: 63
A20: 第3条第3項(6) | C20: 5 | D20: 46209 | E20: =MID("日月火水木金土",WEEKDAY(D20),1) -> 月 | F20: AM9:00 | G20: 現場技術業務 | H20: 業務報告書修正・点検 | J20: 小林主査 | K20: 65
A21: 第3条第3項(6) | C21: 6 | D21: 46210 | E21: =MID("日月火水木金土",WEEKDAY(D21),1) -> 火 | F21: AM9:00 | G21: 現場技術業務 | H21: 現場技術業務 中間検査：検査官：山本係長 | J21: 小林主査 | K21: 66
A22: 第3条第3項(6) | C22: 7 | D22: 46210 | E22: =MID("日月火水木金土",WEEKDAY(D22),1) -> 火 | F22: AM10:00 | G22: 現場技術業務 | H22: 業務検査指摘項目等取り纏め | K22: 66
A23: 第3条第4項 | B23: =INDEX(条文マスタ!$C$5:$C$24,MATCH($A23,条文マスタ!$A$5:$A$24,0)) -> 管理技術者等（監督職員との打合せ・協議） | G23: =INDEX(条文マスタ!$D$5:$D$24,MATCH($A23,条文マスタ!$A$5:$A$24,0)) -> 管理技術者は、特記仕様書に定めるところにより監督職員と打合せ・協議を行い、その結果について相互に確認する（特記仕様書：着手時及び最終時の計2回）。 | I23: =COUNT($C$24:$C$24)&"件" -> 0件 | J23: 実施日数 | K23: =IF(COUNT($C$24:$C$24)=0,0,SUMPRODUCT(($C$24:$C$24<>"")/COUNTIFS($D$24:$D$24,$D$24:$D$24&"")))&"日" -> 0日
A24: 第3条第4項 | H24: 当月該当業務なし
A25: 第5条 | B25: =INDEX(条文マスタ!$C$5:$C$24,MATCH($A25,条文マスタ!$A$5:$A$24,0)) -> 業務処理予定表及び結果報告書 | G25: =INDEX(条文マスタ!$D$5:$D$24,MATCH($A25,条文マスタ!$A$5:$A$24,0)) -> 業務処理予定表及び業務処理結果報告書（実施した業務の内容、その他必要事項）を作成し、監督職員に提出する。 | I25: =COUNT($C$26:$C$47)&"件" -> 22件 | J25: 実施日数 | K25: =IF(COUNT($C$26:$C$47)=0,0,SUMPRODUCT(($C$26:$C$47<>"")/COUNTIFS($D$26:$D$47,$D$26:$D$47&"")))&"日" -> 22日
A26: 第5条 | C26: 1 | D26: 46204 | E26: =MID("日月火水木金土",WEEKDAY(D26),1) -> 水 | F26: AM8:30 | G26: ― | H26: AM8:30 業務内容打合せ（業務処理予定の確認）、PM4:00 業務処理結果報告書作成、PM5:10 翌日作業打合せ（業務処理予定） | J26: 小林主査 | K26: 62 | L26: 日常定型業務（1日1行に集約）
A27: 第5条 | C27: 2 | D27: 46205 | E27: =MID("日月火水木金土",WEEKDAY(D27),1) -> 木 | F27: AM8:30 | G27: ― | H27: AM8:30 業務内容打合せ（業務処理予定の確認）、PM4:00 業務処理結果報告書作成、PM5:10 翌日作業打合せ（業務処理予定） | J27: 小林主査 | K27: 63 | L27: 日常定型業務（1日1行に集約）
A28: 第5条 | C28: 3 | D28: 46206 | E28: =MID("日月火水木金土",WEEKDAY(D28),1) -> 金 | F28: AM8:30 | G28: ― | H28: AM8:30 業務内容打合せ（業務処理予定の確認）、PM4:00 業務処理結果報告書作成、PM5:10 翌日作業打合せ（業務処理予定） | J28: 乾技師 | K28: 64 | L28: 日常定型業務（1日1行に集約）
A29: 第5条 | C29: 4 | D29: 46209 | E29: =MID("日月火水木金土",WEEKDAY(D29),1) -> 月 | F29: AM8:30 | G29: ― | H29: AM8:30 業務内容打合せ（業務処理予定の確認）、PM4:00 業務処理結果報告書作成、PM5:10 翌日作業打合せ（業務処理予定） | J29: 小林主査 | K29: 65 | L29: 日常定型業務（1日1行に集約）
A30: 第5条 | C30: 5 | D30: 46210 | E30: =MID("日月火水木金土",WEEKDAY(D30),1) -> 火 | F30: PM4:00 | G30: ― | H30: PM4:00 業務処理結果報告書作成、PM5:10 翌日作業打合せ（業務処理予定） | K30: 66 | L30: 日常定型業務（1日1行に集約）
A31: 第5条 | C31: 6 | D31: 46211 | E31: =MID("日月火水木金土",WEEKDAY(D31),1) -> 水 | F31: AM8:30 | G31: ― | H31: AM8:30 業務内容打合せ（業務処理予定の確認）、PM4:30 業務処理結果報告書作成、PM5:10 翌日作業打合せ（業務処理予定） | J31: 小林主査 | K31: 67 | L31: 日常定型業務（1日1行に集約）
A32: 第5条 | C32: 7 | D32: 46212 | E32: =MID("日月火水木金土",WEEKDAY(D32),1) -> 木 | F32: AM8:30 | G32: ― | H32: AM8:30 業務内容打合せ（業務処理予定の確認）、PM4:00 業務処理結果報告書作成、PM5:10 翌日作業打合せ（業務処理予定） | J32: 小林主査 | K32: 68 | L32: 日常定型業務（1日1行に集約）
A33: 第5条 | C33: 8 | D33: 46213 | E33: =MID("日月火水木金土",WEEKDAY(D33),1) -> 金 | F33: AM8:30 | G33: ― | H33: AM8:30 業務内容打合せ（業務処理予定の確認）、PM4:00 業務処理結果報告書作成、PM5:10 翌日作業打合せ（業務処理予定） | J33: 小林主査 | K33: 69 | L33: 日常定型業務（1日1行に集約）
A34: 第5条 | C34: 9 | D34: 46216 | E34: =MID("日月火水木金土",WEEKDAY(D34),1) -> 月 | F34: AM8:30 | G34: ― | H34: AM8:30 業務内容打合せ（業務処理予定の確認）、PM4:00 業務処理結果報告書作成、PM5:10 翌日作業打合せ（業務処理予定） | J34: 小林主査 | K34: 70 | L34: 日常定型業務（1日1行に集約）
A35: 第5条 | C35: 10 | D35: 46217 | E35: =MID("日月火水木金土",WEEKDAY(D35),1) -> 火 | F35: AM8:30 | G35: ― | H35: AM8:30 業務内容打合せ（業務処理予定の確認）、PM4:00 業務処理結果報告書作成、PM5:10 翌日作業打合せ（業務処理予定） | J35: 小林主査 | K35: 71 | L35: 日常定型業務（1日1行に集約）
A36: 第5条 | C36: 11 | D36: 46218 | E36: =MID("日月火水木金土",WEEKDAY(D36),1) -> 水 | F36: AM8:30 | G36: ― | H36: AM8:30 業務内容打合せ（業務処理予定の確認）、PM4:30 業務処理結果報告書作成、PM5:10 翌日作業打合せ（業務処理予定） | J36: 乾技師 | K36: 72 | L36: 日常定型業務（1日1行に集約）
A37: 第5条 | C37: 12 | D37: 46219 | E37: =MID("日月火水木金土",WEEKDAY(D37),1) -> 木 | F37: PM4:00 | G37: ― | H37: PM4:00 業務処理結果報告書作成、PM5:10 翌日作業打合せ（業務処理予定） | K37: 73 | L37: 日常定型業務（1日1行に集約）
A38: 第5条 | C38: 13 | D38: 46220 | E38: =MID("日月火水木金土",WEEKDAY(D38),1) -> 金 | F38: AM8:30 | G38: ― | H38: AM8:30 業務内容打合せ（業務処理予定の確認）、PM4:00 業務処理結果報告書作成、PM5:10 翌日作業打合せ（業務処理予定） | J38: 小林主査 | K38: 74 | L38: 日常定型業務（1日1行に集約）
A39: 第5条 | C39: 14 | D39: 46224 | E39: =MID("日月火水木金土",WEEKDAY(D39),1) -> 火 | F39: AM8:30 | G39: ― | H39: AM8:30 業務内容打合せ（業務処理予定の確認）、PM4:30 業務処理結果報告書作成、PM5:10 翌日作業打合せ（業務処理予定） | J39: 小林主査 | K39: 75 | L39: 日常定型業務（1日1行に集約）
A40: 第5条 | C40: 15 | D40: 46225 | E40: =MID("日月火水木金土",WEEKDAY(D40),1) -> 水 | F40: AM8:30 | G40: ― | H40: AM8:30 業務内容打合せ（業務処理予定の確認）、PM4:30 業務処理結果報告書作成、PM5:10 翌日作業打合せ（業務処理予定） | J40: 小林主査 | K40: 76 | L40: 日常定型業務（1日1行に集約）
A41: 第5条 | C41: 16 | D41: 46226 | E41: =MID("日月火水木金土",WEEKDAY(D41),1) -> 木 | F41: PM4:30 | G41: ― | H41: PM4:30 業務処理結果報告書作成、PM5:10 翌日作業打合せ（業務処理予定） | K41: 77 | L41: 日常定型業務（1日1行に集約）
A42: 第5条 | C42: 17 | D42: 46227 | E42: =MID("日月火水木金土",WEEKDAY(D42),1) -> 金 | F42: AM8:30 | G42: ― | H42: AM8:30 業務内容打合せ（業務処理予定の確認）、PM4:00 業務処理結果報告書作成、PM5:10 翌日作業打合せ（業務処理予定） | J42: 乾技師 | K42: 78 | L42: 日常定型業務（1日1行に集約）
...

Sheet 条文別集計
A1: 条文別 実施件数集計表（令和8年7月分）
A2: 「条文別整理表」の件数をCOUNTIFSで集計（件数＝整理表の行数）。
A4: 条文番号 | B4: 章 | C4: 見出し | D4: 46204 | E4: 46205 | F4: 46206 | G4: 46209 | H4: 46210 | I4: 46211 | J4: 46212 | K4: 46213 | L4: 46216 | M4: 46217 | N4: 46218 | O4: 46219 | P4: 46220 | Q4: 46224 | R4: 46225 | S4: 46226 | T4: 46227 | U4: 46230 | V4: 46231 | W4: 46232 | X4: 46233 | Y4: 46234 | Z4: 合計件数 | AA4: 実施日数
D5: =MID("日月火水木金土",WEEKDAY(D4),1) -> 水 | E5: =MID("日月火水木金土",WEEKDAY(E4),1) -> 木 | F5: =MID("日月火水木金土",WEEKDAY(F4),1) -> 金 | G5: =MID("日月火水木金土",WEEKDAY(G4),1) -> 月 | H5: =MID("日月火水木金土",WEEKDAY(H4),1) -> 火 | I5: =MID("日月火水木金土",WEEKDAY(I4),1) -> 水 | J5: =MID("日月火水木金土",WEEKDAY(J4),1) -> 木 | K5: =MID("日月火水木金土",WEEKDAY(K4),1) -> 金 | ... Y5: =MID("日月火水木金土",WEEKDAY(Y4),1) -> 金
A6: 第3条第3項(1) | B6: =INDEX(条文マスタ!$B$5:$B$24,MATCH($A6,条文マスタ!$A$5:$A$24,0)) -> 第1章 総則 | C6: =INDEX(条文マスタ!$C$5:$C$24,MATCH($A6,条文マスタ!$A$5:$A$24,0)) -> 管理技術者等（監督に関する業務の厳正な実施） | D6: =COUNTIFS(条文別整理表!$A$9:$A$135,$A6,条文別整理表!$D$9:$D$135,D$4,条文別整理表!$C$9:$C$135,">0") -> 0 | E6: =COUNTIFS(条文別整理表!$A$9:$A$135,$A6,条文別整理表!$D$9:$D$135,E$4,条文別整理表!$C$9:$C$135,">0") -> 0 | F6: =COUNTIFS(条文別整理表!$A$9:$A$135,$A6,条文別整理表!$D$9:$D$135,F$4,条文別整理表!$C$9:$C$135,">0") -> 0 | G6: =COUNTIFS(条文別整理表!$A$9:$A$135,$A6,条文別整理表!$D$9:$D$135,G$4,条文別整理表!$C$9:$C$135,">0") -> 0 | H6: =COUNTIFS(条文別整理表!$A$9:$A$135,$A6,条文別整理表!$D$9:$D$135,H$4,条文別整理表!$C$9:$C$135,">0") -> 0 | I6: =COUNTIFS(条文別整理表!$A$9:$A$135,$A6,条文別整理表!$D$9:$D$135,I$4,条文別整理表!$C$9:$C$135,">0") -> 0 | J6: =COUNTIFS(条文別整理表!$A$9:$A$135,$A6,条文別整理表!$D$9:$D$135,J$4,条文別整理表!$C$9:$C$135,">0") -> 0 | K6: =COUNTIFS(条文別整理表!$A$9:$A$135,$A6,条文別整理表!$D$9:$D$135,K$4,条文別整理表!$C$9:$C$135,">0") -> 0 | ... Y6: =COUNTIFS(条文別整理表!$A$9:$A$135,$A6,条文別整理表!$D$9:$D$135,Y$4,条文別整理表!$C$9:$C$135,">0") -> 0 | Z6: =SUM(D6:Y6) -> 0 | AA6: =COUNTIF(D6:Y6,">0") -> 0
A7: 第3条第3項(4) | B7: =INDEX(条文マスタ!$B$5:$B$24,MATCH($A7,条文マスタ!$A$5:$A$24,0)) -> 第1章 総則 | C7: =INDEX(条文マスタ!$C$5:$C$24,MATCH($A7,条文マスタ!$A$5:$A$24,0)) -> 管理技術者等（工事請負者等への連絡・通知） | D7: =COUNTIFS(条文別整理表!$A$9:$A$135,$A7,条文別整理表!$D$9:$D$135,D$4,条文別整理表!$C$9:$C$135,">0") -> 0 | E7: =COUNTIFS(条文別整理表!$A$9:$A$135,$A7,条文別整理表!$D$9:$D$135,E$4,条文別整理表!$C$9:$C$135,">0") -> 0 | F7: =COUNTIFS(条文別整理表!$A$9:$A$135,$A7,条文別整理表!$D$9:$D$135,F$4,条文別整理表!$C$9:$C$135,">0") -> 0 | G7: =COUNTIFS(条文別整理表!$A$9:$A$135,$A7,条文別整理表!$D$9:$D$135,G$4,条文別整理表!$C$9:$C$135,">0") -> 0 | H7: =COUNTIFS(条文別整理表!$A$9:$A$135,$A7,条文別整理表!$D$9:$D$135,H$4,条文別整理表!$C$9:$C$135,">0") -> 0 | I7: =COUNTIFS(条文別整理表!$A$9:$A$135,$A7,条文別整理表!$D$9:$D$135,I$4,条文別整理表!$C$9:$C$135,">0") -> 0 | J7: =COUNTIFS(条文別整理表!$A$9:$A$135,$A7,条文別整理表!$D$9:$D$135,J$4,条文別整理表!$C$9:$C$135,">0") -> 0 | K7: =COUNTIFS(条文別整理表!$A$9:$A$135,$A7,条文別整理表!$D$9:$D$135,K$4,条文別整理表!$C$9:$C$135,">0") -> 0 | ... Y7: =COUNTIFS(条文別整理表!$A$9:$A$135,$A7,条文別整理表!$D$9:$D$135,Y$4,条文別整理表!$C$9:$C$135,">0") -> 0 | Z7: =SUM(D7:Y7) -> 0 | AA7: =COUNTIF(D7:Y7,">0") -> 0
A8: 第3条第3項(5) | B8: =INDEX(条文マスタ!$B$5:$B$24,MATCH($A8,条文マスタ!$A$5:$A$24,0)) -> 第1章 総則 | C8: =INDEX(条文マスタ!$C$5:$C$24,MATCH($A8,条文マスタ!$A$5:$A$24,0)) -> 管理技術者等（設計図書の理解・現場状況の精通） | D8: =COUNTIFS(条文別整理表!$A$9:$A$135,$A8,条文別整理表!$D$9:$D$135,D$4,条文別整理表!$C$9:$C$135,">0") -> 0 | E8: =COUNTIFS(条文別整理表!$A$9:$A$135,$A8,条文別整理表!$D$9:$D$135,E$4,条文別整理表!$C$9:$C$135,">0") -> 0 | F8: =COUNTIFS(条文別整理表!$A$9:$A$135,$A8,条文別整理表!$D$9:$D$135,F$4,条文別整理表!$C$9:$C$135,">0") -> 0 | G8: =COUNTIFS(条文別整理表!$A$9:$A$135,$A8,条文別整理表!$D$9:$D$135,G$4,条文別整理表!$C$9:$C$135,">0") -> 0 | H8: =COUNTIFS(条文別整理表!$A$9:$A$135,$A8,条文別整理表!$D$9:$D$135,H$4,条文別整理表!$C$9:$C$135,">0") -> 1 | I8: =COUNTIFS(条文別整理表!$A$9:$A$135,$A8,条文別整理表!$D$9:$D$135,I$4,条文別整理表!$C$9:$C$135,">0") -> 0 | J8: =COUNTIFS(条文別整理表!$A$9:$A$135,$A8,条文別整理表!$D$9:$D$135,J$4,条文別整理表!$C$9:$C$135,">0") -> 0 | K8: =COUNTIFS(条文別整理表!$A$9:$A$135,$A8,条文別整理表!$D$9:$D$135,K$4,条文別整理表!$C$9:$C$135,">0") -> 0 | ... Y8: =COUNTIFS(条文別整理表!$A$9:$A$135,$A8,条文別整理表!$D$9:$D$135,Y$4,条文別整理表!$C$9:$C$135,">0") -> 0 | Z8: =SUM(D8:Y8) -> 1 | AA8: =COUNTIF(D8:Y8,">0") -> 1
A9: 第3条第3項(6) | B9: =INDEX(条文マスタ!$B$5:$B$24,MATCH($A9,条文マスタ!$A$5:$A$24,0)) -> 第1章 総則 | C9: =INDEX(条文マスタ!$C$5:$C$24,MATCH($A9,条文マスタ!$A$5:$A$24,0)) -> 管理技術者等（図書の整理） | D9: =COUNTIFS(条文別整理表!$A$9:$A$135,$A9,条文別整理表!$D$9:$D$135,D$4,条文別整理表!$C$9:$C$135,">0") -> 2 | E9: =COUNTIFS(条文別整理表!$A$9:$A$135,$A9,条文別整理表!$D$9:$D$135,E$4,条文別整理表!$C$9:$C$135,">0") -> 2 | F9: =COUNTIFS(条文別整理表!$A$9:$A$135,$A9,条文別整理表!$D$9:$D$135,F$4,条文別整理表!$C$9:$C$135,">0") -> 0 | G9: =COUNTIFS(条文別整理表!$A$9:$A$135,$A9,条文別整理表!$D$9:$D$135,G$4,条文別整理表!$C$9:$C$135,">0") -> 1 | H9: =COUNTIFS(条文別整理表!$A$9:$A$135,$A9,条文別整理表!$D$9:$D$135,H$4,条文別整理表!$C$9:$C$135,">0") -> 2 | I9: =COUNTIFS(条文別整理表!$A$9:$A$135,$A9,条文別整理表!$D$9:$D$135,I$4,条文別整理表!$C$9:$C$135,">0") -> 0 | J9: =COUNTIFS(条文別整理表!$A$9:$A$135,$A9,条文別整理表!$D$9:$D$135,J$4,条文別整理表!$C$9:$C$135,">0") -> 0 | K9: =COUNTIFS(条文別整理表!$A$9:$A$135,$A9,条文別整理表!$D$9:$D$135,K$4,条文別整理表!$C$9:$C$135,">0") -> 0 | ... Y9: =COUNTIFS(条文別整理表!$A$9:$A$135,$A9,条文別整理表!$D$9:$D$135,Y$4,条文別整理表!$C$9:$C$135,">0") -> 0 | Z9: =SUM(D9:Y9) -> 7 | AA9: =COUNTIF(D9:Y9,">0") -> 4
A10: 第3条第4項 | B10: =INDEX(条文マスタ!$B$5:$B$24,MATCH($A10,条文マスタ!$A$5:$A$24,0)) -> 第1章 総則 | C10: =INDEX(条文マスタ!$C$5:$C$24,MATCH($A10,条文マスタ!$A$5:$A$24,0)) -> 管理技術者等（監督職員との打合せ・協議） | D10: =COUNTIFS(条文別整理表!$A$9:$A$135,$A10,条文別整理表!$D$9:$D$135,D$4,条文別整理表!$C$9:$C$135,">0") -> 0 | E10: =COUNTIFS(条文別整理表!$A$9:$A$135,$A10,条文別整理表!$D$9:$D$135,E$4,条文別整理表!$C$9:$C$135,">0") -> 0 | F10: =COUNTIFS(条文別整理表!$A$9:$A$135,$A10,条文別整理表!$D$9:$D$135,F$4,条文別整理表!$C$9:$C$135,">0") -> 0 | G10: =COUNTIFS(条文別整理表!$A$9:$A$135,$A10,条文別整理表!$D$9:$D$135,G$4,条文別整理表!$C$9:$C$135,">0") -> 0 | H10: =COUNTIFS(条文別整理表!$A$9:$A$135,$A10,条文別整理表!$D$9:$D$135,H$4,条文別整理表!$C$9:$C$135,">0") -> 0 | I10: =COUNTIFS(条文別整理表!$A$9:$A$135,$A10,条文別整理表!$D$9:$D$135,I$4,条文別整理表!$C$9:$C$135,">0") -> 0 | J10: =COUNTIFS(条文別整理表!$A$9:$A$135,$A10,条文別整理表!$D$9:$D$135,J$4,条文別整理表!$C$9:$C$135,">0") -> 0 | K10: =COUNTIFS(条文別整理表!$A$9:$A$135,$A10,条文別整理表!$D$9:$D$135,K$4,条文別整理表!$C$9:$C$135,">0") -> 0 | ... Y10: =COUNTIFS(条文別整理表!$A$9:$A$135,$A10,条文別整理表!$D$9:$D$135,Y$4,条文別整理表!$C$9:$C$135,">0") -> 0 | Z10: =SUM(D10:Y10) -> 0 | AA10: =COUNTIF(D10:Y10,">0") -> 0
A11: 第5条 | B11: =INDEX(条文マスタ!$B$5:$B$24,MATCH($A11,条文マスタ!$A$5:$A$24,0)) -> 第1章 総則 | C11: =INDEX(条文マスタ!$C$5:$C$24,MATCH($A11,条文マスタ!$A$5:$A$24,0)) -> 業務処理予定表及び結果報告書 | D11: =COUNTIFS(条文別整理表!$A$9:$A$135,$A11,条文別整理表!$D$9:$D$135,D$4,条文別整理表!$C$9:$C$135,">0") -> 1 | E11: =COUNTIFS(条文別整理表!$A$9:$A$135,$A11,条文別整理表!$D$9:$D$135,E$4,条文別整理表!$C$9:$C$135,">0") -> 1 | F11: =COUNTIFS(条文別整理表!$A$9:$A$135,$A11,条文別整理表!$D$9:$D$135,F$4,条文別整理表!$C$9:$C$135,">0") -> 1 | G11: =COUNTIFS(条文別整理表!$A$9:$A$135,$A11,条文別整理表!$D$9:$D$135,G$4,条文別整理表!$C$9:$C$135,">0") -> 1 | H11: =COUNTIFS(条文別整理表!$A$9:$A$135,$A11,条文別整理表!$D$9:$D$135,H$4,条文別整理表!$C$9:$C$135,">0") -> 1 | I11: =COUNTIFS(条文別整理表!$A$9:$A$135,$A11,条文別整理表!$D$9:$D$135,I$4,条文別整理表!$C$9:$C$135,">0") -> 1 | J11: =COUNTIFS(条文別整理表!$A$9:$A$135,$A11,条文別整理表!$D$9:$D$135,J$4,条文別整理表!$C$9:$C$135,">0") -> 1 | K11: =COUNTIFS(条文別整理表!$A$9:$A$135,$A11,条文別整理表!$D$9:$D$135,K$4,条文別整理表!$C$9:$C$135,">0") -> 1 | ... Y11: =COUNTIFS(条文別整理表!$A$9:$A$135,$A11,条文別整理表!$D$9:$D$135,Y$4,条文別整理表!$C$9:$C$135,">0") -> 1 | Z11: =SUM(D11:Y11) -> 22 | AA11: =COUNTIF(D11:Y11,">0") -> 22
A12: 第6条 | B12: =INDEX(条文マスタ!$B$5:$B$24,MATCH($A12,条文マスタ!$A$5:$A$24,0)) -> 第1章 総則 | C12: =INDEX(条文マスタ!$C$5:$C$24,MATCH($A12,条文マスタ!$A$5:$A$24,0)) -> 業務完了時の提出書類 | D12: =COUNTIFS(条文別整理表!$A$9:$A$135,$A12,条文別整理表!$D$9:$D$135,D$4,条文別整理表!$C$9:$C$135,">0") -> 0 | E12: =COUNTIFS(条文別整理表!$A$9:$A$135,$A12,条文別整理表!$D$9:$D$135,E$4,条文別整理表!$C$9:$C$135,">0") -> 0 | F12: =COUNTIFS(条文別整理表!$A$9:$A$135,$A12,条文別整理表!$D$9:$D$135,F$4,条文別整理表!$C$9:$C$135,">0") -> 0 | G12: =COUNTIFS(条文別整理表!$A$9:$A$135,$A12,条文別整理表!$D$9:$D$135,G$4,条文別整理表!$C$9:$C$135,">0") -> 0 | H12: =COUNTIFS(条文別整理表!$A$9:$A$135,$A12,条文別整理表!$D$9:$D$135,H$4,条文別整理表!$C$9:$C$135,">0") -> 0 | I12: =COUNTIFS(条文別整理表!$A$9:$A$135,$A12,条文別整理表!$D$9:$D$135,I$4,条文別整理表!$C$9:$C$135,">0") -> 0 | J12: =COUNTIFS(条文別整理表!$A$9:$A$135,$A12,条文別整理表!$D$9:$D$135,J$4,条文別整理表!$C$9:$C$135,">0") -> 0 | K12: =COUNTIFS(条文別整理表!$A$9:$A$135,$A12,条文別整理表!$D$9:$D$135,K$4,条文別整理表!$C$9:$C$135,">0") -> 0 | ... Y12: =COUNTIFS(条文別整理表!$A$9:$A$135,$A12,条文別整理表!$D$9:$D$135,Y$4,条文別整理表!$C$9:$C$135,">0") -> 0 | Z12: =SUM(D12:Y12) -> 0 | AA12: =COUNTIF(D12:Y12,">0") -> 0
A13: 第7条 | B13: =INDEX(条文マスタ!$B$5:$B$24,MATCH($A13,条文マスタ!$A$5:$A$24,0)) -> 第2章 監督に関する現場技術業務 | C13: =INDEX(条文マスタ!$C$5:$C$24,MATCH($A13,条文マスタ!$A$5:$A$24,0)) -> 書類の確認 | D13: =COUNTIFS(条文別整理表!$A$9:$A$135,$A13,条文別整理表!$D$9:$D$135,D$4,条文別整理表!$C$9:$C$135,">0") -> 0 | E13: =COUNTIFS(条文別整理表!$A$9:$A$135,$A13,条文別整理表!$D$9:$D$135,E$4,条文別整理表!$C$9:$C$135,">0") -> 0 | F13: =COUNTIFS(条文別整理表!$A$9:$A$135,$A13,条文別整理表!$D$9:$D$135,F$4,条文別整理表!$C$9:$C$135,">0") -> 0 | G13: =COUNTIFS(条文別整理表!$A$9:$A$135,$A13,条文別整理表!$D$9:$D$135,G$4,条文別整理表!$C$9:$C$135,">0") -> 0 | H13: =COUNTIFS(条文別整理表!$A$9:$A$135,$A13,条文別整理表!$D$9:$D$135,H$4,条文別整理表!$C$9:$C$135,">0") -> 0 | I13: =COUNTIFS(条文別整理表!$A$9:$A$135,$A13,条文別整理表!$D$9:$D$135,I$4,条文別整理表!$C$9:$C$135,">0") -> 0 | J13: =COUNTIFS(条文別整理表!$A$9:$A$135,$A13,条文別整理表!$D$9:$D$135,J$4,条文別整理表!$C$9:$C$135,">0") -> 0 | K13: =COUNTIFS(条文別整理表!$A$9:$A$135,$A13,条文別整理表!$D$9:$D$135,K$4,条文別整理表!$C$9:$C$135,">0") -> 0 | ... Y13: =COUNTIFS(条文別整理表!$A$9:$A$135,$A13,条文別整理表!$D$9:$D$135,Y$4,条文別整理表!$C$9:$C$135,">0") -> 0 | Z13: =SUM(D13:Y13) -> 2 | AA13: =COUNTIF(D13:Y13,">0") -> 2
A14: 第8条 | B14: =INDEX(条文マスタ!$B$5:$B$24,MATCH($A14,条文マスタ!$A$5:$A$24,0)) -> 第2章 監督に関する現場技術業務 | C14: =INDEX(条文マスタ!$C$5:$C$24,MATCH($A14,条文マスタ!$A$5:$A$24,0)) -> 立会 | D14: =COUNTIFS(条文別整理表!$A$9:$A$135,$A14,条文別整理表!$D$9:$D$135,D$4,条文別整理表!$C$9:$C$135,">0") -> 0 | E14: =COUNTIFS(条文別整理表!$A$9:$A$135,$A14,条文別整理表!$D$9:$D$135,E$4,条文別整理表!$C$9:$C$135,">0") -> 0 | F14: =COUNTIFS(条文別整理表!$A$9:$A$135,$A14,条文別整理表!$D$9:$D$135,F$4,条文別整理表!$C$9:$C$135,">0") -> 0 | G14: =COUNTIFS(条文別整理表!$A$9:$A$135,$A14,条文別整理表!$D$9:$D$135,G$4,条文別整理表!$C$9:$C$135,">0") -> 0 | H14: =COUNTIFS(条文別整理表!$A$9:$A$135,$A14,条文別整理表!$D$9:$D$135,H$4,条文別整理表!$C$9:$C$135,">0") -> 1 | I14: =COUNTIFS(条文別整理表!$A$9:$A$135,$A14,条文別整理表!$D$9:$D$135,I$4,条文別整理表!$C$9:$C$135,">0") -> 2 | J14: =COUNTIFS(条文別整理表!$A$9:$A$135,$A14,条文別整理表!$D$9:$D$135,J$4,条文別整理表!$C$9:$C$135,">0") -> 0 | K14: =COUNTIFS(条文別整理表!$A$9:$A$135,$A14,条文別整理表!$D$9:$D$135,K$4,条文別整理表!$C$9:$C$135,">0") -> 0 | ... Y14: =COUNTIFS(条文別整理表!$A$9:$A$135,$A14,条文別整理表!$D$9:$D$135,Y$4,条文別整理表!$C$9:$C$135,">0") -> 0 | Z14: =SUM(D14:Y14) -> 8 | AA14: =COUNTIF(D14:Y14,">0") -> 6
A15: 第9条 | B15: =INDEX(条文マスタ!$B$5:$B$24,MATCH($A15,条文マスタ!$A$5:$A$24,0)) -> 第2章 監督に関する現場技術業務 | C15: =INDEX(条文マスタ!$C$5:$C$24,MATCH($A15,条文マスタ!$A$5:$A$24,0)) -> 検測 | D15: =COUNTIFS(条文別整理表!$A$9:$A$135,$A15,条文別整理表!$D$9:$D$135,D$4,条文別整理表!$C$9:$C$135,">0") -> 0 | E15: =COUNTIFS(条文別整理表!$A$9:$A$135,$A15,条文別整理表!$D$9:$D$135,E$4,条文別整理表!$C$9:$C$135,">0") -> 0 | F15: =COUNTIFS(条文別整理表!$A$9:$A$135,$A15,条文別整理表!$D$9:$D$135,F$4,条文別整理表!$C$9:$C$135,">0") -> 0 | G15: =COUNTIFS(条文別整理表!$A$9:$A$135,$A15,条文別整理表!$D$9:$D$135,G$4,条文別整理表!$C$9:$C$135,">0") -> 0 | H15: =COUNTIFS(条文別整理表!$A$9:$A$135,$A15,条文別整理表!$D$9:$D$135,H$4,条文別整理表!$C$9:$C$135,">0") -> 0 | I15: =COUNTIFS(条文別整理表!$A$9:$A$135,$A15,条文別整理表!$D$9:$D$135,I$4,条文別整理表!$C$9:$C$135,">0") -> 0 | J15: =COUNTIFS(条文別整理表!$A$9:$A$135,$A15,条文別整理表!$D$9:$D$135,J$4,条文別整理表!$C$9:$C$135,">0") -> 0 | K15: =COUNTIFS(条文別整理表!$A$9:$A$135,$A15,条文別整理表!$D$9:$D$135,K$4,条文別整理表!$C$9:$C$135,">0") -> 0 | ... Y15: =COUNTIFS(条文別整理表!$A$9:$A$135,$A15,条文別整理表!$D$9:$D$135,Y$4,条文別整理表!$C$9:$C$135,">0") -> 0 | Z15: =SUM(D15:Y15) -> 0 | AA15: =COUNTIF(D15:Y15,">0") -> 0
A16: 第10条 | B16: =INDEX(条文マスタ!$B$5:$B$24,MATCH($A16,条文マスタ!$A$5:$A$24,0)) -> 第2章 監督に関する現場技術業務 | C16: =INDEX(条文マスタ!$C$5:$C$24,MATCH($A16,条文マスタ!$A$5:$A$24,0)) -> 材料検査 | D16: =COUNTIFS(条文別整理表!$A$9:$A$135,$A16,条文別整理表!$D$9:$D$135,D$4,条文別整理表!$C$9:$C$135,">0") -> 0 | E16: =COUNTIFS(条文別整理表!$A$9:$A$135,$A16,条文別整理表!$D$9:$D$135,E$4,条文別整理表!$C$9:$C$135,">0") -> 0 | F16: =COUNTIFS(条文別整理表!$A$9:$A$135,$A16,条文別整理表!$D$9:$D$135,F$4,条文別整理表!$C$9:$C$135,">0") -> 0 | G16: =COUNTIFS(条文別整理表!$A$9:$A$135,$A16,条文別整理表!$D$9:$D$135,G$4,条文別整理表!$C$9:$C$135,">0") -> 0 | H16: =COUNTIFS(条文別整理表!$A$9:$A$135,$A16,条文別整理表!$D$9:$D$135,H$4,条文別整理表!$C$9:$C$135,">0") -> 0 | I16: =COUNTIFS(条文別整理表!$A$9:$A$135,$A16,条文別整理表!$D$9:$D$135,I$4,条文別整理表!$C$9:$C$135,">0") -> 0 | J16: =COUNTIFS(条文別整理表!$A$9:$A$135,$A16,条文別整理表!$D$9:$D$135,J$4,条文別整理表!$C$9:$C$135,">0") -> 0 | K16: =COUNTIFS(条文別整理表!$A$9:$A$135,$A16,条文別整理表!$D$9:$D$135,K$4,条文別整理表!$C$9:$C$135,">0") -> 0 | ... Y16: =COUNTIFS(条文別整理表!$A$9:$A$135,$A16,条文別整理表!$D$9:$D$135,Y$4,条文別整理表!$C$9:$C$135,">0") -> 0 | Z16: =SUM(D16:Y16) -> 0 | AA16: =COUNTIF(D16:Y16,">0") -> 0
A17: 第11条 | B17: =INDEX(条文マスタ!$B$5:$B$24,MATCH($A17,条文マスタ!$A$5:$A$24,0)) -> 第2章 監督に関する現場技術業務 | C17: =INDEX(条文マスタ!$C$5:$C$24,MATCH($A17,条文マスタ!$A$5:$A$24,0)) -> 工程管理 | D17: =COUNTIFS(条文別整理表!$A$9:$A$135,$A17,条文別整理表!$D$9:$D$135,D$4,条文別整理表!$C$9:$C$135,">0") -> 1 | E17: =COUNTIFS(条文別整理表!$A$9:$A$135,$A17,条文別整理表!$D$9:$D$135,E$4,条文別整理表!$C$9:$C$135,">0") -> 0 | F17: =COUNTIFS(条文別整理表!$A$9:$A$135,$A17,条文別整理表!$D$9:$D$135,F$4,条文別整理表!$C$9:$C$135,">0") -> 0 | G17: =COUNTIFS(条文別整理表!$A$9:$A$135,$A17,条文別整理表!$D$9:$D$135,G$4,条文別整理表!$C$9:$C$135,">0") -> 0 | H17: =COUNTIFS(条文別整理表!$A$9:$A$135,$A17,条文別整理表!$D$9:$D$135,H$4,条文別整理表!$C$9:$C$135,">0") -> 0 | I17: =COUNTIFS(条文別整理表!$A$9:$A$135,$A17,条文別整理表!$D$9:$D$135,I$4,条文別整理表!$C$9:$C$135,">0") -> 0 | J17: =COUNTIFS(条文別整理表!$A$9:$A$135,$A17,条文別整理表!$D$9:$D$135,J$4,条文別整理表!$C$9:$C$135,">0") -> 0 | K17: =COUNTIFS(条文別整理表!$A$9:$A$135,$A17,条文別整理表!$D$9:$D$135,K$4,条文別整理表!$C$9:$C$135,">0") -> 1 | ... Y17: =COUNTIFS(条文別整理表!$A$9:$A$135,$A17,条文別整理表!$D$9:$D$135,Y$4,条文別整理表!$C$9:$C$135,">0") -> 0 | Z17: =SUM(D17:Y17) -> 3 | AA17: =COUNTIF(D17:Y17,">0") -> 3
... A25: 第20条 | B25: =INDEX(条文マスタ!$B$5:$B$24,MATCH($A25,条文マスタ!$A$5:$A$24,0)) -> 第3章 設計に関する現場技術業務 | C25: =INDEX(条文マスタ!$C$5:$C$24,MATCH($A25,条文マスタ!$A$5:$A$24,0)) -> 設計に必要な資料 | D25: =COUNTIFS(条文別整理表!$A$9:$A$135,$A25,条文別整理表!$D$9:$D$135,D$4,条文別整理表!$C$9:$C$135,">0") -> 0 | E25: =COUNTIFS(条文別整理表!$A$9:$A$135,$A25,条文別整理表!$D$9:$D$135,E$4,条文別整理表!$C$9:$C$135,">0") -> 0 | F25: =COUNTIFS(条文別整理表!$A$9:$A$135,$A25,条文別整理表!$D$9:$D$135,F$4,条文別整理表!$C$9:$C$135,">0") -> 0 | G25: =COUNTIFS(条文別整理表!$A$9:$A$135,$A25,条文別整理表!$D$9:$D$135,G$4,条文別整理表!$C$9:$C$135,">0") -> 0 | H25: =COUNTIFS(条文別整理表!$A$9:$A$135,$A25,条文別整理表!$D$9:$D$135,H$4,条文別整理表!$C$9:$C$135,">0") -> 0 | I25: =COUNTIFS(条文別整理表!$A$9:$A$135,$A25,条文別整理表!$D$9:$D$135,I$4,条文別整理表!$C$9:$C$135,">0") -> 1 | J25: =COUNTIFS(条文別整理表!$A$9:$A$135,$A25,条文別整理表!$D$9:$D$135,J$4,条文別整理表!$C$9:$C$135,">0") -> 0 | K25: =COUNTIFS(条文別整理表!$A$9:$A$135,$A25,条文別整理表!$D$9:$D$135,K$4,条文別整理表!$C$9:$C$135,">0") -> 2 | ... Y25: =COUNTIFS(条文別整理表!$A$9:$A$135,$A25,条文別整理表!$D$9:$D$135,Y$4,条文別整理表!$C$9:$C$135,">0") -> 0 | Z25: =SUM(D25:Y25) -> 9 | AA25: =COUNTIF(D25:Y25,">0") -> 5
A26: 合計 | D26: =SUM(D6:D25) -> 4 | E26: =SUM(E6:E25) -> 3 | F26: =SUM(F6:F25) -> 4 | G26: =SUM(G6:G25) -> 4 | H26: =SUM(H6:H25) -> 5 | I26: =SUM(I6:I25) -> 4 | J26: =SUM(J6:J25) -> 3 | K26: =SUM(K6:K25) -> 5 | ... Z26: =SUM(Z6:Z25) -> 97 | AA26: =SUMPRODUCT(--(D26:Y26>0)) -> 22
A28: ※ 合計行の「実施日数」は7月の業務実施日数（履行日数）。「－」は当月該当業務なし。

Sheet 条文マスタ
A1: 条文マスタ（現場技術業務委託共通仕様書 条文一覧）
A2: 出典：現場技術業務委託共通仕様書（京都府、令和元年8月20日 元指第486号 最終改正）別添2 及び 現場技術業務 特記仕様書。条文要旨は原文を要約したもの。
A4: 条文番号 | B4: 章 | C4: 見出し | D4: 条文要旨
A5: 第3条第3項(1) | B5: 第1章 総則 | C5: 管理技術者等（監督に関する業務の厳正な実施） | D5: 必要な監督に関する業務を厳正に実施すること。
A6: 第3条第3項(4) | B6: 第1章 総則 | C6: 管理技術者等（工事請負者等への連絡・通知） | D6: 工事請負者又は外部への連絡若しくは通知を行う場合には、その内容を相手に正確に伝えること。
A7: 第3条第3項(5) | B7: 第1章 総則 | C7: 管理技術者等（設計図書の理解・現場状況の精通） | D7: 請負工事の契約書及び設計図書等の内容を十分理解し、更に工事現場の状況についても精通しておくこと。
A8: 第3条第3項(6) | B8: 第1章 総則 | C8: 管理技術者等（図書の整理） | D8: 業務の実施にあたっては、業務に関する図書を適切に整理しておくこと。
A9: 第3条第4項 | B9: 第1章 総則 | C9: 管理技術者等（監督職員との打合せ・協議） | D9: 管理技術者は、特記仕様書に定めるところにより監督職員と打合せ・協議を行い、その結果について相互に確認する（特記仕様書：着手時及び最終時の計2回）。
A10: 第5条 | B10: 第1章 総則 | C10: 業務処理予定表及び結果報告書 | D10: 業務処理予定表及び業務処理結果報告書（実施した業務の内容、その他必要事項）を作成し、監督職員に提出する。
A11: 第6条 | B11: 第1章 総則 | C11: 業務完了時の提出書類 | D11: 業務完了時に、業務処理結果報告書を一括整理して提出する。
A12: 第7条 | B12: 第2章 監督に関する現場技術業務 | C12: 書類の確認 | D12: 工事請負者から提出された書類は、これを確認し監督職員に報告しなければならない。
A13: 第8条 | B13: 第2章 監督に関する現場技術業務 | C13: 立会 | D13: 設計図書に基づき立会いを行った場合は、その結果を書面で監督職員に報告する。
A14: 第9条 | B14: 第2章 監督に関する現場技術業務 | C14: 検測 | D14: 請負工事の施工が設計図書に示す所定の出来形及び品質を確保するため現地で検測を行い、その成果を監督職員に提出する。
A15: 第10条 | B15: 第2章 監督に関する現場技術業務 | C15: 材料検査 | D15: 材料検査を実施したときは、検査年月日・品名・寸法等・検査数量・検査結果及び合格数量等を付記して監督職員に提出する。
... A24: 第20条 | B24: 第3章 設計に関する現場技術業務 | C24: 設計に必要な資料 | D24: 設計に必要な図面、数量取りまとめ、各種データの作成等を、事前に監督職員と協議の上行い、結果を書面で提出する。
