Workbook

Sheet 現場確認日一覧
A1: 現場確認日一覧及び考えられる安全対策（令和8年7月～9月）
A2: 出典：業務処理結果報告書（令和8年7月分 №62～83、8月分 №84～103、9月分 №104～122）。執務室業務・河川砂防課での打合せ・書面検査は除外。安全対策は類型ごとに考えられるもの（日報に実施記録はない）。
A4: No. | B4: 実施日 | C4: 曜 | D4: 天候 | E4: 報告書№ | F4: 開始時刻 | G4: 類型 | H4: 工事・業務名 | I4: 場所 | J4: 内容 | K4: 担当監督員 | L4: 受注者等 | M4: 想定される主な危険 | N4: 考えられる主な安全対策（詳細は類型別シート） | O4: 当日の留意点
A5: 令和8年7月
A6: 1 | B6: 46204 | C6: =MID("日月火水木金土",WEEKDAY(B6),1) -> 水 | D6: 曇り | E6: 62 | F6: AM10:00 | G6: B | H6: 管内一円(竹野川他)府民協働型インフラ保全工事 | I6: 峰山・五箇 鱒留川 | J6: 現場進捗状況確認 | K6: 小林主査 | L6: ㈱修己建設 | M6: 重機・工事車両との接触、法面転落、増水 | N6: 現場代理人へ連絡し受注者の安全指示に従う／保護帽・安全靴・反射ベスト着用／重機旋回範囲に入らない／水位確認 | O6: ・夏季：熱中症対策（WBGT確認・水分塩分補給・休憩）
A7: 2 | B7: 46206 | C7: =MID("日月火水木金土",WEEKDAY(B7),1) -> 金 | D7: 晴れ | E7: 64 | F7: AM10:00 | G7: A | H7: 久僧海岸/吉野川河口 定期観測 | I7: 丹後町久僧（久僧海岸・吉野川河口） | J7: 観測調査作業 | K7: 小林主査 | L7: ― | M7: 水際転落・高波、転倒、熱中症 | N7: 気象・波浪・潮位を事前確認／波打ち際・消波ブロックに立ち入らない／水際ではライフジャケット着用／2人以上で行動 | O7: ・夏季：熱中症対策（WBGT確認・水分塩分補給・休憩）
A8: 3 | B8: 46206 | C8: =MID("日月火水木金土",WEEKDAY(B8),1) -> 金 | D8: 晴れ | E8: 64 | F8: AM11:00 | G8: D | H8: 宇川 現況既設井堰調査 | I8: 丹後町鞍内 １箇所 | J8: 既設井堰の現況調査（１箇所） | K8: 吉良係長 | L8: ― | M8: 堰体上での転倒・転落、増水、野生生物 | N8: 堰体上を歩かない／流水中は胴長・ライフジャケット着用／2人以上で行動／地元・水利関係者へ事前連絡／クマ鈴携帯 | O8: ・夏季：熱中症対策（WBGT確認・水分塩分補給・休憩）
A9: 4 | B9: 46206 | C9: =MID("日月火水木金土",WEEKDAY(B9),1) -> 金 | D9: 晴れ | E9: 64 | F9: PM1:30 | G9: D | H9: 宇川 現況既設井堰調査 | I9: 弥栄町野中他 ３箇所 | J9: 既設井堰の現況調査（３箇所） | K9: 吉良係長 | L9: ― | M9: 堰体上での転倒・転落、増水、野生生物 | N9: 堰体上を歩かない／流水中は胴長・ライフジャケット着用／2人以上で行動／地元・水利関係者へ事前連絡／クマ鈴携帯 | O9: ・夏季：熱中症対策（WBGT確認・水分塩分補給・休憩）
A10: 5 | B10: 46209 | C10: =MID("日月火水木金土",WEEKDAY(B10),1) -> 月 | D10: 雨/曇り | E10: 65 | F10: PM1:30 | G10: A | H10: 新樋越川河口 定期観測 | I10: 新樋越川河口 | J10: 観測調査作業 | K10: 小林主査 | L10: ― | M10: 水際転落・高波、転倒、熱中症 | N10: 気象・波浪・潮位を事前確認／波打ち際・消波ブロックに立ち入らない／水際ではライフジャケット着用／2人以上で行動 | O10: ・雨天：足元の滑り、河川・水路の増水に注意。観測・立会の実施可否を判断 ・夏季：熱中症対策（WBGT確認・水分塩分補給・休憩）
A11: 6 | B11: 46210 | C11: =MID("日月火水木金土",WEEKDAY(B11),1) -> 火 | D11: 曇り/晴れ | E11: 66 | F11: PM1:00 | G11: B | H11: 管内一円（河梨川他）府民協働型インフラ保全工事 | I11: 久美浜・川上谷川 | J11: 現場状況確認 | K11: 倉垣副主査 | L11: 西田建設㈱ | M11: 重機・工事車両との接触、法面転落、増水 | N11: 現場代理人へ連絡し受注者の安全指示に従う／保護帽・安全靴・反射ベスト着用／重機旋回範囲に入らない／水位確認 | O11: ・夏季：熱中症対策（WBGT確認・水分塩分補給・休憩）
A12: 7 | B12: 46210 | C12: =MID("日月火水木金土",WEEKDAY(B12),1) -> 火 | D12: 曇り/晴れ | E12: 66 | F12: PM2:00 | G12: B | H12: 管内一円（河梨川他）府民協働型インフラ保全工事 | I12: 久美浜・川上谷川 | J12: 現場立会 | K12: 倉垣副主査 | L12: 西田建設㈱ | M12: 重機・工事車両との接触、法面転落、増水 | N12: 現場代理人へ連絡し受注者の安全指示に従う／保護帽・安全靴・反射ベスト着用／重機旋回範囲に入らない／水位確認 | O12: ・夏季：熱中症対策（WBGT確認・水分塩分補給・休憩）
A13: 8 | B13: 46211 | C13: =MID("日月火水木金土",WEEKDAY(B13),1) -> 水 | D13: 晴れ | E13: 67 | F13: AM9:30 | G13: B | H13: 管内一円(竹野川他)府民協働型インフラ保全工事 | I13: 大宮・三重 竹野川 | J13: 確認立会 | K13: 小林主査 | L13: ㈱修己建設 | M13: 重機・工事車両との接触、法面転落、増水 | N13: 現場代理人へ連絡し受注者の安全指示に従う／保護帽・安全靴・反射ベスト着用／重機旋回範囲に入らない／水位確認 | O13: ・夏季：熱中症対策（WBGT確認・水分塩分補給・休憩）
A14: 9 | B14: 46211 | C14: =MID("日月火水木金土",WEEKDAY(B14),1) -> 水 | D14: 晴れ | E14: 67 | F14: AM11:00 | G14: B | H14: 管内一円(竹野川他)府民協働型インフラ保全工事 | I14: 峰山・五箇 鱒留川 | J14: 確認立会 | K14: 小林主査 | L14: ㈱修己建設 | M14: 重機・工事車両との接触、法面転落、増水 | N14: 現場代理人へ連絡し受注者の安全指示に従う／保護帽・安全靴・反射ベスト着用／重機旋回範囲に入らない／水位確認 | O14: ・夏季：熱中症対策（WBGT確認・水分塩分補給・休憩）
A15: 10 | B15: 46213 | C15: =MID("日月火水木金土",WEEKDAY(B15),1) -> 金 | D15: 晴れ | E15: 69 | F15: AM11:00 | G15: D | H15: 宇川 現況既設井堰調査 | I15: 弥栄町野中他 ３箇所 | J15: 既設井堰の現況調査（３箇所） | K15: 吉良係長 | L15: ― | M15: 堰体上での転倒・転落、増水、野生生物 | N15: 堰体上を歩かない／流水中は胴長・ライフジャケット着用／2人以上で行動／地元・水利関係者へ事前連絡／クマ鈴携帯 | O15: ・夏季：熱中症対策（WBGT確認・水分塩分補給・休憩）
A16: 11 | B16: 46213 | C16: =MID("日月火水木金土",WEEKDAY(B16),1) -> 金 | D16: 晴れ | E16: 69 | F16: PM1:00 | G16: B | H16: 管内一円(竹野川他)府民協働型インフラ保全工事 | I16: 大宮・三重 竹野川 | J16: 現場進捗状況確認 | K16: 小林主査 | L16: ㈱修己建設 | M16: 重機・工事車両との接触、法面転落、増水 | N16: 現場代理人へ連絡し受注者の安全指示に従う／保護帽・安全靴・反射ベスト着用／重機旋回範囲に入らない／水位確認 | O16: ・夏季：熱中症対策（WBGT確認・水分塩分補給・休憩）
A17: 12 | B17: 46219 | C17: =MID("日月火水木金土",WEEKDAY(B17),1) -> 木 | D17: 晴れ | E17: 73 | F17: AM9:00 | G17: B | H17: 管内一円（河梨川他）府民協働型インフラ保全工事 | I17: 久美浜・川上谷川 | J17: 確認立会 | K17: 倉垣副主査 | L17: 西田建設㈱ | M17: 重機・工事車両との接触、法面転落、増水 | N17: 現場代理人へ連絡し受注者の安全指示に従う／保護帽・安全靴・反射ベスト着用／重機旋回範囲に入らない／水位確認 | O17: ・夏季：熱中症対策（WBGT確認・水分塩分補給・休憩）
... A30: 25 | B30: 46234 | C30: =MID("日月火水木金土",WEEKDAY(B30),1) -> 金 | D30: 晴れ | E30: 83 | F30: PM1:00 | G30: A | H30: 新樋越川河口 定期観測 | I30: 新樋越川河口 | J30: 観測調査作業 | K30: 小林主査 | L30: ― | M30: 水際転落・高波、転倒、熱中症 | N30: 気象・波浪・潮位を事前確認／波打ち際・消波ブロックに立ち入らない／水際ではライフジャケット着用／2人以上で行動 | O30: ・夏季：熱中症対策（WBGT確認・水分塩分補給・休憩）
A31: 令和8年8月
A32: 26 | B32: 46238 | C32: =MID("日月火水木金土",WEEKDAY(B32),1) -> 火 | D32: 晴れ | E32: 85 | F32: AM9:00 | G32: B | H32: 管内一円（河梨川他）府民協働型インフラ保全工事 | I32: 久美浜・川上谷川 | J32: 確認立会 | K32: 倉垣副主査 | L32: 西田建設㈱ | M32: 重機・工事車両との接触、法面転落、増水 | N32: 現場代理人へ連絡し受注者の安全指示に従う／保護帽・安全靴・反射ベスト着用／重機旋回範囲に入らない／水位確認 | O32: ・夏季：熱中症対策（WBGT確認・水分塩分補給・休憩）
A33: 27 | B33: 46246 | C33: =MID("日月火水木金土",WEEKDAY(B33),1) -> 水 | D33: 雨/曇り | E33: 90 | F33: AM9:30 | G33: B | H33: 管内一円（河梨川他）府民協働型インフラ保全工事 | I33: 久美浜・川上谷川 | J33: 現場進捗状況確認 | K33: 倉垣副主査 | L33: 西田建設㈱ | M33: 重機・工事車両との接触、法面転落、増水 | N33: 現場代理人へ連絡し受注者の安全指示に従う／保護帽・安全靴・反射ベスト着用／重機旋回範囲に入らない／水位確認 | O33: ・雨天：足元の滑り、河川・水路の増水に注意。観測・立会の実施可否を判断 ・夏季：熱中症対策（WBGT確認・水分塩分補給・休憩）
A34: 28 | B34: 46246 | C34: =MID("日月火水木金土",WEEKDAY(B34),1) -> 水 | D34: 雨/曇り | E34: 90 | F34: AM10:30 | G34: A | H34: 木津川河口 定期観測 | I34: 網野町（木津川河口） | J34: 定期観測箇所の現況確認 | K34: 吉良係長 | L34: ― | M34: 水際転落・高波、転倒、熱中症 | N34: 気象・波浪・潮位を事前確認／波打ち際・消波ブロックに立ち入らない／水際ではライフジャケット着用／2人以上で行動 | O34: ・雨天：足元の滑り、河川・水路の増水に注意。観測・立会の実施可否を判断 ・夏季：熱中症対策（WBGT確認・水分塩分補給・休憩）
A35: 29 | B35: 46246 | C35: =MID("日月火水木金土",WEEKDAY(B35),1) -> 水 | D35: 雨/曇り | E35: 90 | F35: AM11:30 | G35: A | H35: 宇川河口/久僧海岸 定期観測 | I35: 丹後町上野・久僧 | J35: 定期観測箇所の現況確認 | K35: 吉良係長 | L35: ― | M35: 水際転落・高波、転倒、熱中症 | N35: 気象・波浪・潮位を事前確認／波打ち際・消波ブロックに立ち入らない／水際ではライフジャケット着用／2人以上で行動 | O35: ・雨天：足元の滑り、河川・水路の増水に注意。観測・立会の実施可否を判断 ・夏季：熱中症対策（WBGT確認・水分塩分補給・休憩）
A36: 30 | B36: 46248 | C36: =MID("日月火水木金土",WEEKDAY(B36),1) -> 金 | D36: 晴れ | E36: 92 | F36: AM9:30 | G36: A | H36: 木津川河口 定期観測 | I36: 網野町（木津川河口） | J36: 観測調査作業 | K36: 小林主査 | L36: ― | M36: 水際転落・高波、転倒、熱中症 | N36: 気象・波浪・潮位を事前確認／波打ち際・消波ブロックに立ち入らない／水際ではライフジャケット着用／2人以上で行動 | O36: ・夏季：熱中症対策（WBGT確認・水分塩分補給・休憩）
A37: 31 | B37: 46248 | C37: =MID("日月火水木金土",WEEKDAY(B37),1) -> 金 | D37: 晴れ | E37: 92 | F37: AM11:00 | G37: A | H37: 宇川河口 定期観測 | I37: 丹後町上野（宇川河口） | J37: 観測調査作業 | K37: 小林主査 | L37: ― | M37: 水際転落・高波、転倒、熱中症 | N37: 気象・波浪・潮位を事前確認／波打ち際・消波ブロックに立ち入らない／水際ではライフジャケット着用／2人以上で行動 | O37: ・夏季：熱中症対策（WBGT確認・水分塩分補給・休憩）
A38: 32 | B38: 46248 | C38: =MID("日月火水木金土",WEEKDAY(B38),1) -> 金 | D38: 晴れ | E38: 92 | F38: PM1:00 | G38: A | H38: 久僧海岸/吉野川河口 定期観測 | I38: 丹後町久僧（久僧海岸・吉野川河口） | J38: 観測調査作業 | K38: 小林主査 | L38: ― | M38: 水際転落・高波、転倒、熱中症 | N38: 気象・波浪・潮位を事前確認／波打ち際・消波ブロックに立ち入らない／水際ではライフジャケット着用／2人以上で行動 | O38: ・夏季：熱中症対策（WBGT確認・水分塩分補給・休憩）
A39: 33 | B39: 46255 | C39: =MID("日月火水木金土",WEEKDAY(B39),1) -> 金 | D39: 晴れ | E39: 97 | F39: AM9:30 | G39: B | H39: 管内一円（河梨川他）府民協働型インフラ保全工事 | I39: 久美浜・川上谷川 | J39: 確認立会 | K39: 倉垣副主査 | L39: 西田建設㈱ | M39: 重機・工事車両との接触、法面転落、増水 | N39: 現場代理人へ連絡し受注者の安全指示に従う／保護帽・安全靴・反射ベスト着用／重機旋回範囲に入らない／水位確認 | O39: ・夏季：熱中症対策（WBGT確認・水分塩分補給・休憩）
A40: 34 | B40: 46261 | C40: =MID("日月火水木金土",WEEKDAY(B40),1) -> 木 | D40: 曇り/雨 | E40: 101 | F40: PM11:30 | G40: A | H40: 久僧海岸/吉野川河口 定期観測 | I40: 丹後町久僧（久僧海岸・吉野川河口） | J40: 観測調査作業 | K40: 小林主査 | L40: ― | M40: 水際転落・高波、転倒、熱中症 | N40: 気象・波浪・潮位を事前確認／波打ち際・消波ブロックに立ち入らない／水際ではライフジャケット着用／2人以上で行動 | O40: ・雨天：足元の滑り、河川・水路の増水に注意。観測・立会の実施可否を判断 ・夏季：熱中症対策（WBGT確認・水分塩分補給・休憩） ・※日報の開始時刻「PM11:30」はAM11:30の誤記と思われる
A41: 35 | B41: 46261 | C41: =MID("日月火水木金土",WEEKDAY(B41),1) -> 木 | D41: 曇り/雨 | E41: 101 | F41: PM1:00 | G41: A | H41: 宇川河口 定期観測 | I41: 丹後町上野（宇川河口） | J41: 観測調査作業 | K41: 小林主査 | L41: ― | M41: 水際転落・高波、転倒、熱中症 | N41: 気象・波浪・潮位を事前確認／波打ち際・消波ブロックに立ち入らない／水際ではライフジャケット着用／2人以上で行動 | O41: ・雨天：足元の滑り、河川・水路の増水に注意。観測・立会の実施可否を判断 ・夏季：熱中症対策（WBGT確認・水分塩分補給・休憩）
A42: 36 | B42: 46261 | C42: =MID("日月火水木金土",WEEKDAY(B42),1) -> 木 | D42: 曇り/雨 | E42: 101 | F42: PM2:30 | G42: A | H42: 木津川河口 定期観測 | I42: 網野町（木津川河口） | J42: 観測調査作業 | K42: 小林主査 | L42: ― | M42: 水際転落・高波、転倒、熱中症 | N42: 気象・波浪・潮位を事前確認／波打ち際・消波ブロックに立ち入らない／水際ではライフジャケット着用／2人以上で行動 | O42: ・雨天：足元の滑り、河川・水路の増水に注意。観測・立会の実施可否を判断 ・夏季：熱中症対策（WBGT確認・水分塩分補給・休憩）
A43: 37 | B43: 46262 | C43: =MID("日月火水木金土",WEEKDAY(B43),1) -> 金 | D43: 曇り/晴れ | E43: 102 | F43: AM9:30 | G43: B | H43: 管内一円（河梨川他）府民協働型インフラ保全工事 | I43: 久美浜・川上谷川 | J43: 確認立会 | K43: 倉垣副主査 | L43: 西田建設㈱ | M43: 重機・工事車両との接触、法面転落、増水 | N43: 現場代理人へ連絡し受注者の安全指示に従う／保護帽・安全靴・反射ベスト着用／重機旋回範囲に入らない／水位確認 | O43: ・夏季：熱中症対策（WBGT確認・水分塩分補給・休憩）
A44: 38 | B44: 46265 | C44: =MID("日月火水木金土",WEEKDAY(B44),1) -> 月 | D44: 晴れ | E44: 103 | F44: AM10:00 | G44: B | H44: 管内一円（河梨川他）府民協働型インフラ保全工事 | I44: 久美浜・川上谷川 | J44: 確認立会 | K44: 倉垣副主査 | L44: 西田建設㈱ | M44: 重機・工事車両との接触、法面転落、増水 | N44: 現場代理人へ連絡し受注者の安全指示に従う／保護帽・安全靴・反射ベスト着用／重機旋回範囲に入らない／水位確認 | O44: ・夏季：熱中症対策（WBGT確認・水分塩分補給・休憩）
A45: 令和8年9月
A46: 39 | B46: 46268 | C46: =MID("日月火水木金土",WEEKDAY(B46),1) -> 木 | D46: 曇り/雨 | E46: 106 | F46: PM1:30 | G46: B | H46: 川上谷川緊急浚渫推進（河川）工事 | I46: 久美浜町金谷・畑地区 | J46: 現場立会 | K46: 小林主査 | L46: 小野澤建材㈱ | M46: 重機・工事車両との接触、法面転落、増水 | N46: 現場代理人へ連絡し受注者の安全指示に従う／保護帽・安全靴・反射ベスト着用／重機旋回範囲に入らない／水位確認 | O46: ・雨天：足元の滑り、河川・水路の増水に注意。観測・立会の実施可否を判断
A47: 40 | B47: 46276 | C47: =MID("日月火水木金土",WEEKDAY(B47),1) -> 金 | D47: 雨/曇り | E47: 112 | F47: PM1:30 | G47: A | H47: 木津川河口 定期観測 | I47: 網野町（木津川河口） | J47: 観測調査作業 | K47: 小林主査 | L47: ― | M47: 水際転落・高波、転倒、熱中症 | N47: 気象・波浪・潮位を事前確認／波打ち際・消波ブロックに立ち入らない／水際ではライフジャケット着用／2人以上で行動 | O47: ・雨天：足元の滑り、河川・水路の増水に注意。観測・立会の実施可否を判断
A48: 41 | B48: 46276 | C48: =MID("日月火水木金土",WEEKDAY(B48),1) -> 金 | D48: 雨/曇り | E48: 112 | F48: PM2:30 | G48: A | H48: 宇川河口 定期観測 | I48: 丹後町上野（宇川河口） | J48: 観測調査作業 | K48: 小林主査 | L48: ― | M48: 水際転落・高波、転倒、熱中症 | N48: 気象・波浪・潮位を事前確認／波打ち際・消波ブロックに立ち入らない／水際ではライフジャケット着用／2人以上で行動 | O48: ・雨天：足元の滑り、河川・水路の増水に注意。観測・立会の実施可否を判断
A49: 42 | B49: 46276 | C49: =MID("日月火水木金土",WEEKDAY(B49),1) -> 金 | D49: 雨/曇り | E49: 112 | F49: PM3:00 | G49: A | H49: 久僧海岸/吉野川河口 定期観測 | I49: 丹後町久僧（久僧海岸・吉野川河口） | J49: 観測調査作業 | K49: 小林主査 | L49: ― | M49: 水際転落・高波、転倒、熱中症 | N49: 気象・波浪・潮位を事前確認／波打ち際・消波ブロックに立ち入らない／水際ではライフジャケット着用／2人以上で行動 | O49: ・雨天：足元の滑り、河川・水路の増水に注意。観測・立会の実施可否を判断
A50: 43 | B50: 46282 | C50: =MID("日月火水木金土",WEEKDAY(B50),1) -> 木 | D50: 晴れ/曇り | E50: 116 | F50: PM2:00 | G50: B | H50: 竹野川他府民協働型インフラ保全工事 | I50: ― | J50: 竣工検査立会 | K50: 小林主査 | L50: ㈱修己建設 | M50: 重機・工事車両との接触、法面転落、増水 | N50: 現場代理人へ連絡し受注者の安全指示に従う／保護帽・安全靴・反射ベスト着用／重機旋回範囲に入らない／水位確認 | O50: ・夏季：熱中症対策（WBGT確認・水分塩分補給・休憩） ・検査官・監督員と同行。完成箇所の法面・護岸上の移動に注意
A51: 44 | B51: 46283 | C51: =MID("日月火水木金土",WEEKDAY(B51),1) -> 金 | D51: 晴れ/曇り | E51: 117 | F51: PM1:30 | G51: E | H51: 管内一円（成願寺川）緊急浚渫推進（砂防）工事 | I51: ― | J51: 現場調査 | K51: 小林主査 | L51: サンキ工業㈱ | M51: 急斜面・落石、渓流での転倒、野生生物 | N51: 受注者と同行し経路を事前確認／保護帽着用・上下作業を避ける／クマ鈴携帯・単独行動禁止 | O51: ・夏季：熱中症対策（WBGT確認・水分塩分補給・休憩）
A52: 45 | B52: 46289 | C52: =MID("日月火水木金土",WEEKDAY(B52),1) -> 木 | D52: 晴れ | E52: 118 | F52: AM10:00 | G52: A | H52: 木津川河口 定期観測 | I52: 網野町（木津川河口） | J52: 観測調査作業 | K52: 小林主査 | L52: ― | M52: 水際転落・高波、転倒、熱中症 | N52: 気象・波浪・潮位を事前確認／波打ち際・消波ブロックに立ち入らない／水際ではライフジャケット着用／2人以上で行動
A53: 46 | B53: 46289 | C53: =MID("日月火水木金土",WEEKDAY(B53),1) -> 木 | D53: 晴れ | E53: 118 | F53: AM11:00 | G53: A | H53: 宇川河口 定期観測 | I53: 丹後町上野（宇川河口） | J53: 観測調査作業 | K53: 小林主査 | L53: ― | M53: 水際転落・高波、転倒、熱中症 | N53: 気象・波浪・潮位を事前確認／波打ち際・消波ブロックに立ち入らない／水際ではライフジャケット着用／2人以上で行動
...

Sheet 安全対策（類型別）
A1: 現場確認業務の類型別 想定される危険と安全対策
A2: 業務処理結果報告書（令和8年7～9月）の現場業務から類型を整理し、各類型で考えられる安全対策をまとめたもの（日報に記載された実施記録ではない）。
A4: 類型 | B4: 業務の種類 | C4: 想定される主な危険 | D4: 考えられる安全対策
A5: A | B5: 河口・海岸の定期観測・現況確認 | C5: ・波浪、高潮、離岸流による水際での転落・流され ・砂浜、消波ブロック、岩場、濡れた護岸での転倒 ・強風・落雷 ・熱中症、単独作業時の急病 | D5: ・出発前に気象警報、波浪・潮位（潮汐表）、風速を確認し、高波・強風・雷のおそれがあれば中止・延期する ・波打ち際、消波ブロック上、濡れた護岸には立ち入らない（観測は安全な位置から行う） ・水際に近づく場合はライフジャケットを着用する ・滑りにくい靴を履き、両手が空く装備（ザック等）とする ・原則2人以上で行動し、行先・帰着予定を事務所に連絡する ・退避経路と車両の駐車位置（波・浸水の届かない場所）を事前に確認する
A6: B | B6: 河川工事現場の立会・進捗確認・竣工検査（現場） | C6: ・稼働中の重機（バックホウ旋回範囲）、ダンプ等の工事車両との接触 ・法面、護岸、仮設通路での転倒・転落 ・河川内作業区域での急な増水 ・熱中症 | D6: ・現場到着時に現場代理人へ連絡し、受注者の安全指示・誘導に従う（新規入場時は受注者の安全教育・KY活動に参加） ・保護帽、安全靴、反射ベストを着用する ・重機の旋回範囲、ダンプの走行経路に立ち入らない。近づく必要があるときはオペレーター・誘導員に合図して作業を止めてもらう ・法肩、水際、仮締切の上には不用意に近づかない ・上流の降雨・河川水位を確認し、増水のおそれがあれば河川内に立ち入らない ・身分証明書を携帯する（特記仕様書「現場への立入り等」）
A7: C | B7: 残土仮置場・残土処理場の確認立会 | C7: ・ダンプの出入り、重機の敷均し作業との接触 ・盛土法面の崩壊、軟弱な盛土上での足元の不安定 ・粉じん | D7: ・出入口でダンプの動線と誘導員の配置を確認し、指示に従う ・盛土の上や法肩に乗らず、締固めの済んだ箇所から確認する ・保護帽、安全靴、反射ベストを着用する ・敷地内では車両を指定の場所に停め、徒歩移動は重機の死角を避ける
A8: D | B8: 既設井堰の現況調査（宇川） | C8: ・堰体上や堰直下での転倒・転落、苔による滑り ・流水中の歩行、急な増水 ・ハチ、ヘビ、ツキノワグマ等の野生生物 ・水田・水路の私有地への立入り | D8: ・堰体の上を歩かない。流水中に入る場合は胴長・ライフジャケットを着用し、水深・流速を確認する ・2人以上で行動し、1人は岸から見守る ・事前に地元・水利関係者へ調査日時を連絡し、私有地は了解を得てから立ち入る ・クマ鈴を携帯し、ハチの巣に注意する。長袖・長ズボン・手袋を着用する ・前日・当日の降雨と河川水位を確認する
A9: E | B9: 砂防工事の現場調査（渓流部） | C9: ・急斜面、転石、落石 ・渓流での転倒・増水 ・ツキノワグマ、ハチ等の野生生物 | D9: ・受注者と同行し、調査範囲・経路を事前に打ち合わせる ・保護帽を着用し、斜面の下側に人がいるときは上で行動しない ・クマ鈴を携帯し、単独行動をしない ・降雨後・降雨中は渓流内に立ち入らない
A10: 共通 | B10: 全現場共通 | C10: ・車両での移動中の交通事故 ・路肩駐車時の後続車との接触 ・熱中症（7～9月） ・雨天時のスリップ、落雷 | D10: ・行先・同行者・帰着予定を事務所の行動予定に記入し、携帯電話で連絡が取れるようにする ・路肩に駐車する場合はハザードランプ・三角表示板を使用し、車道側に出ない ・WBGT（暑さ指数）を確認し、水分・塩分を補給し、こまめに休憩する。体調不良時は作業を中止する ・雷鳴が聞こえたら直ちに車内等へ退避する ・保護帽、安全靴を常備し、身分証明書を携帯する

Sheet 月別集計
A1: 月別 現場確認の実施状況（令和8年7月～9月）
A3: 月 | B3: 履行日数 | C3: 現場確認日数 | D3: 現場確認の割合 | E3: 現場確認件数 | F3: 類型A | G3: 類型B | H3: 類型C | I3: 類型D | J3: 類型E
A4: 7月 | B4: 22 | C4: =SUMPRODUCT((現場確認日一覧!$B$5:$B$55>=DATE(2026,7,1))*(現場確認日一覧!$B$5:$B$55<DATE(2026,8,1))/COUNTIF(現場確認日一覧!$B$5:$B$55,現場確認日一覧!$B$5:$B$55&"")) -> 13 | D4: =IF(B4=0,0,C4/B4) -> 0.59090909 | E4: =COUNTIFS(現場確認日一覧!$B$5:$B$55,">="&DATE(2026,7,1),現場確認日一覧!$B$5:$B$55,"<"&DATE(2026,8,1)) -> 25 | F4: =COUNTIFS(現場確認日一覧!$B$5:$B$55,">="&DATE(2026,7,1),現場確認日一覧!$B$5:$B$55,"<"&DATE(2026,8,1),現場確認日一覧!$G$5:$G$55,"A") -> 9 | G4: =COUNTIFS(現場確認日一覧!$B$5:$B$55,">="&DATE(2026,7,1),現場確認日一覧!$B$5:$B$55,"<"&DATE(2026,8,1),現場確認日一覧!$G$5:$G$55,"B") -> 11 | H4: =COUNTIFS(現場確認日一覧!$B$5:$B$55,">="&DATE(2026,7,1),現場確認日一覧!$B$5:$B$55,"<"&DATE(2026,8,1),現場確認日一覧!$G$5:$G$55,"C") -> 2 | I4: =COUNTIFS(現場確認日一覧!$B$5:$B$55,">="&DATE(2026,7,1),現場確認日一覧!$B$5:$B$55,"<"&DATE(2026,8,1),現場確認日一覧!$G$5:$G$55,"D") -> 3 | J4: =COUNTIFS(現場確認日一覧!$B$5:$B$55,">="&DATE(2026,7,1),現場確認日一覧!$B$5:$B$55,"<"&DATE(2026,8,1),現場確認日一覧!$G$5:$G$55,"E") -> 0
A5: 8月 | B5: 20 | C5: =SUMPRODUCT((現場確認日一覧!$B$5:$B$55>=DATE(2026,8,1))*(現場確認日一覧!$B$5:$B$55<DATE(2026,9,1))/COUNTIF(現場確認日一覧!$B$5:$B$55,現場確認日一覧!$B$5:$B$55&"")) -> 7 | D5: =IF(B5=0,0,C5/B5) -> 0.35 | E5: =COUNTIFS(現場確認日一覧!$B$5:$B$55,">="&DATE(2026,8,1),現場確認日一覧!$B$5:$B$55,"<"&DATE(2026,9,1)) -> 13 | F5: =COUNTIFS(現場確認日一覧!$B$5:$B$55,">="&DATE(2026,8,1),現場確認日一覧!$B$5:$B$55,"<"&DATE(2026,9,1),現場確認日一覧!$G$5:$G$55,"A") -> 8 | G5: =COUNTIFS(現場確認日一覧!$B$5:$B$55,">="&DATE(2026,8,1),現場確認日一覧!$B$5:$B$55,"<"&DATE(2026,9,1),現場確認日一覧!$G$5:$G$55,"B") -> 5 | H5: =COUNTIFS(現場確認日一覧!$B$5:$B$55,">="&DATE(2026,8,1),現場確認日一覧!$B$5:$B$55,"<"&DATE(2026,9,1),現場確認日一覧!$G$5:$G$55,"C") -> 0 | I5: =COUNTIFS(現場確認日一覧!$B$5:$B$55,">="&DATE(2026,8,1),現場確認日一覧!$B$5:$B$55,"<"&DATE(2026,9,1),現場確認日一覧!$G$5:$G$55,"D") -> 0 | J5: =COUNTIFS(現場確認日一覧!$B$5:$B$55,">="&DATE(2026,8,1),現場確認日一覧!$B$5:$B$55,"<"&DATE(2026,9,1),現場確認日一覧!$G$5:$G$55,"E") -> 0
A6: 9月 | B6: 19 | C6: =SUMPRODUCT((現場確認日一覧!$B$5:$B$55>=DATE(2026,9,1))*(現場確認日一覧!$B$5:$B$55<DATE(2026,10,1))/COUNTIF(現場確認日一覧!$B$5:$B$55,現場確認日一覧!$B$5:$B$55&"")) -> 6 | D6: =IF(B6=0,0,C6/B6) -> 0.31578947 | E6: =COUNTIFS(現場確認日一覧!$B$5:$B$55,">="&DATE(2026,9,1),現場確認日一覧!$B$5:$B$55,"<"&DATE(2026,10,1)) -> 10 | F6: =COUNTIFS(現場確認日一覧!$B$5:$B$55,">="&DATE(2026,9,1),現場確認日一覧!$B$5:$B$55,"<"&DATE(2026,10,1),現場確認日一覧!$G$5:$G$55,"A") -> 6 | G6: =COUNTIFS(現場確認日一覧!$B$5:$B$55,">="&DATE(2026,9,1),現場確認日一覧!$B$5:$B$55,"<"&DATE(2026,10,1),現場確認日一覧!$G$5:$G$55,"B") -> 3 | H6: =COUNTIFS(現場確認日一覧!$B$5:$B$55,">="&DATE(2026,9,1),現場確認日一覧!$B$5:$B$55,"<"&DATE(2026,10,1),現場確認日一覧!$G$5:$G$55,"C") -> 0 | I6: =COUNTIFS(現場確認日一覧!$B$5:$B$55,">="&DATE(2026,9,1),現場確認日一覧!$B$5:$B$55,"<"&DATE(2026,10,1),現場確認日一覧!$G$5:$G$55,"D") -> 0 | J6: =COUNTIFS(現場確認日一覧!$B$5:$B$55,">="&DATE(2026,9,1),現場確認日一覧!$B$5:$B$55,"<"&DATE(2026,10,1),現場確認日一覧!$G$5:$G$55,"E") -> 1
A7: 合計 | B7: =SUM(B4:B6) -> 61 | C7: =SUM(C4:C6) -> 26 | D7: =IF(B7=0,0,C7/B7) -> 0.42622951 | E7: =SUM(E4:E6) -> 48 | F7: =SUM(F4:F6) -> 23 | G7: =SUM(G4:G6) -> 19 | H7: =SUM(H4:H6) -> 2 | I7: =SUM(I4:I6) -> 3 | J7: =SUM(J4:J6) -> 1
A9: ※ 履行日数（青字）は業務処理結果報告書の枚数（7月22日、8月20日、9月19日）。
A10: ※ 現場確認日数は「現場確認日一覧」の実施日の重複を除いた日数。件数は一覧の行数。
A11: ※ 類型A：河口・海岸の定期観測・現況確認
A12: ※ 類型B：河川工事現場の立会・進捗確認・竣工検査（現場）
A13: ※ 類型C：残土仮置場・残土処理場の確認立会
A14: ※ 類型D：既設井堰の現況調査（宇川）
A15: ※ 類型E：砂防工事の現場調査（渓流部）

Sheet 参考（現地か不明）
A1: 参考：現地で実施した可能性があるが、日報からは判断できない業務（一覧・集計には含めていない）
A3: 実施日 | B3: 報告書№ | C3: 開始時刻 | D3: 工事・業務名 | E3: 内容 | F3: 担当監督員 | G3: 受注者等 | H3: 除外理由
A4: 46226 | B4: 77 | C4: PM1:30 | D4: 工事完成下検査（主任監督員） | E4: 浅茂川海岸なぎさ緊急保全工事 | F4: 小林主査 | G4: ㈱修己建設 | H4: 工事完成下検査は書面中心と考えられるが、現地確認を含む可能性がある
A5: 46260 | B5: 100 | C5: PM3:00 | D5: 川上谷川緊急浚渫推進（河川）工事 | E5: 工事着手前打合せ | F5: 小林主査 | G5: ― | H5: 打合せ場所の記載がない
A6: 46274 | B6: 110 | C6: PM1:30 | D6: 工事完成下検査（主任監督員） | E6: 竹野川他府民協働インフラ工事 | F6: 小林主査 | G6: ㈱修己建設 | H6: 工事完成下検査は書面中心と考えられるが、現地確認を含む可能性がある
A7: 46294 | B7: 121 | C7: AM8:30 | D7: 竹野川（小西川）広域河川改修（補正・防災安全）工事 | E7: 工事初回打合せ | F7: 倉垣副主査 | G7: ㈱丸正組 | H7: 打合せ場所の記載がない
